2024-09-02 20:19:03,710 : INFO : Start of Training
2024-09-02 20:19:03,710 : INFO : Run_id:2024-09-02_201903_356348343
2024-09-02 20:19:03,710 : INFO : Start of Data Load, validation and transformation
2024-09-02 20:19:03,710 : INFO : Start of Archiving Old Rejected Files...
2024-09-02 20:19:03,710 : INFO : End of Archiving Old Rejected Files...
2024-09-02 20:19:03,710 : INFO : Start of Archiving Old Validated Files...
2024-09-02 20:19:03,710 : INFO : End of Archiving Old Validated Files...
2024-09-02 20:19:03,710 : INFO : Start of Archiving Old Processed Files...
2024-09-02 20:19:03,710 : INFO : End of Archiving Old Processed Files...
2024-09-02 20:19:03,710 : INFO : Start of Archiving Old Result Files...
2024-09-02 20:19:03,710 : INFO : End of Archiving Old Result Files...
2024-09-02 20:19:03,710 : INFO : Start of Reading values From Schema...
2024-09-02 20:19:03,710 : INFO : End of Reading values From Schema...
2024-09-02 20:19:03,710 : INFO : Start of Validating Column Length...
2024-09-02 20:19:03,710 : ERROR : OSError raised while Validating Column Length
Traceback (most recent call last):
  File "C:\Users\SHUBHAM MURTADAK\project1\project2\ML_v1\apps\ingestion\load_validate.py", line 89, in validate_column_length
    for file in listdir(self.data_path):
                ^^^^^^^^^^^^^^^^^^^^^^^
OSError: [WinError 123] The filename, directory name, or volume label syntax is incorrect: 'data\training_data_processed'
2024-09-02 20:19:03,710 : ERROR : Unsuccessful End of Data Load, validation and transformation
Traceback (most recent call last):
  File "C:\Users\SHUBHAM MURTADAK\project1\project2\ML_v1\apps\ingestion\load_validate.py", line 89, in validate_column_length
    for file in listdir(self.data_path):
                ^^^^^^^^^^^^^^^^^^^^^^^
OSError: [WinError 123] The filename, directory name, or volume label syntax is incorrect: 'data\training_data_processed'

During handling of the above exception, another exception occurred:

Traceback (most recent call last):
  File "C:\Users\SHUBHAM MURTADAK\project1\project2\ML_v1\apps\ingestion\load_validate.py", line 298, in validate_trainset
    self.validate_column_length(number_of_columns)
  File "C:\Users\SHUBHAM MURTADAK\project1\project2\ML_v1\apps\ingestion\load_validate.py", line 104, in validate_column_length
    raise OSError
OSError
2024-09-02 20:19:03,710 : ERROR : Unsuccessful End of Training
Traceback (most recent call last):
  File "C:\Users\SHUBHAM MURTADAK\project1\project2\ML_v1\apps\ingestion\load_validate.py", line 89, in validate_column_length
    for file in listdir(self.data_path):
                ^^^^^^^^^^^^^^^^^^^^^^^
OSError: [WinError 123] The filename, directory name, or volume label syntax is incorrect: 'data\training_data_processed'

During handling of the above exception, another exception occurred:

Traceback (most recent call last):
  File "C:\Users\SHUBHAM MURTADAK\project1\project2\ML_v1\apps\ingestion\load_validate.py", line 298, in validate_trainset
    self.validate_column_length(number_of_columns)
  File "C:\Users\SHUBHAM MURTADAK\project1\project2\ML_v1\apps\ingestion\load_validate.py", line 104, in validate_column_length
    raise OSError
OSError

During handling of the above exception, another exception occurred:

Traceback (most recent call last):
  File "C:\Users\SHUBHAM MURTADAK\project1\project2\ML_v1\apps\training\train_model.py", line 59, in training_model
    self.loadValidate.validate_trainset()
  File "C:\Users\SHUBHAM MURTADAK\project1\project2\ML_v1\apps\ingestion\load_validate.py", line 314, in validate_trainset
    raise Exception
Exception
